Workbook

Sheet Planilha1
A1: matched_ID | B1: (Vários itens)
G2: ID | H2: MATCHED_ID
A3: Soma de ipp | G3: 1529 | H3: =VLOOKUP(G3,Sheet1!$A:$BN,66,0) -> 220604
A4: id | B4: Total | E4: 3 | F4: ultimoStatus.nome | G4: =VLOOKUP(G$3,Sheet1!$A:$BN,$E4,0) -> GERSON VILAS-BÔAS | H4: =VLOOKUP(H$3,Sheet1!$A:$BN,$E4,0) -> Marcos Tavares
A5: 1529 | B5: 0.17297393 | E5: 4 | F5: ultimoStatus.siglaPartido | G5: =VLOOKUP(G$3,Sheet1!$A:$BN,$E5,0) -> PMDB | H5: =VLOOKUP(H$3,Sheet1!$A:$BN,$E5,0) -> PDT
A6: 1538 | B6: 0.17694364 | E6: 5 | F6: sexo | G6: =VLOOKUP(G$3,Sheet1!$A:$BN,$E6,0) -> M | H6: =VLOOKUP(H$3,Sheet1!$A:$BN,$E6,0) -> M
A7: 62926 | B7: 0.22046409 | E7: 6 | F7: dataNascimento | G7: =VLOOKUP(G$3,Sheet1!$A:$BN,$E7,0) -> 1934-11-01 | H7: =VLOOKUP(H$3,Sheet1!$A:$BN,$E7,0) -> 1978-01-28
A8: 66828 | B8: 1.0049649 | E8: 7 | F8: escolaridade | G8: =VLOOKUP(G$3,Sheet1!$A:$BN,$E8,0) -> Superior | H8: =VLOOKUP(H$3,Sheet1!$A:$BN,$E8,0) -> Pós-Graduação
A9: 67312 | B9: 0.2255696 | E9: 8 | F9: idade_posse | G9: =VLOOKUP(G$3,Sheet1!$A:$BN,$E9,0) -> 52 | H9: =VLOOKUP(H$3,Sheet1!$A:$BN,$E9,0) -> 45
A10: 73438 | B10: 0.26472232 | E10: 9 | F10: tempo_atuacao_dias | G10: =VLOOKUP(G$3,Sheet1!$A:$BN,$E10,0) -> 1460 | H10: =VLOOKUP(H$3,Sheet1!$A:$BN,$E10,0) -> 603
A11: 73464 | B11: 0.87315106 | E11: 10 | F11: tempo_atuacao_percent | G11: =VLOOKUP(G$3,Sheet1!$A:$BN,$E11,0) -> 1 | H11: =VLOOKUP(H$3,Sheet1!$A:$BN,$E11,0) -> 1.06
A12: 73476 | B12: 0.26300902 | E12: 11 | F12: mesa_1 | G12: =VLOOKUP(G$3,Sheet1!$A:$BN,$E12,0) -> 0 | H12: =VLOOKUP(H$3,Sheet1!$A:$BN,$E12,0) -> 0
A13: 73483 | B13: 1.6330625 | E13: 12 | F13: mesa_2 | G13: =VLOOKUP(G$3,Sheet1!$A:$BN,$E13,0) -> 0 | H13: =VLOOKUP(H$3,Sheet1!$A:$BN,$E13,0) -> 0
A14: 73489 | B14: 0.16142132 | E14: 13 | F14: pos_lider | G14: =VLOOKUP(G$3,Sheet1!$A:$BN,$E14,0) -> 0 | H14: =VLOOKUP(H$3,Sheet1!$A:$BN,$E14,0) -> 0
A15: 73495 | B15: 0.52345841 | E15: 14 | F15: pos_comiss_pr | G15: =VLOOKUP(G$3,Sheet1!$A:$BN,$E15,0) -> 0 | H15: =VLOOKUP(H$3,Sheet1!$A:$BN,$E15,0) -> 0
A16: 73554 | B16: 0.40425699 | E16: 15 | F16: relatorias | G16: =VLOOKUP(G$3,Sheet1!$A:$BN,$E16,0) -> 0 | H16: =VLOOKUP(H$3,Sheet1!$A:$BN,$E16,0) -> 29
... A66: 74444 | B66: 0.6298982 | E66: 65 | F66: is_evangelico | G66: =VLOOKUP(G$3,Sheet1!$A:$BN,$E66,0) -> TRUE | H66: =VLOOKUP(H$3,Sheet1!$A:$BN,$E66,0) -> FALSE
A67: 74451 | B67: 0.56219531
A68: 74479 | B68: 0.5551562
A69: 74481 | B69: 0.21596419
A70: 74483 | B70: 0.20990159
A71: 74526 | B71: 0.22208499
A72: 74540 | B72: 0.99353567
A73: 74567 | B73: 0.51729948
A74: 74577 | B74: 0.62374691
A75: 74581 | B75: 1.3673177
A76: 74582 | B76: 0.27927782
A77: 74585 | B77: 3.0257205
A78: 74632 | B78: 0.53966015
... A445: 220712 | B445: 0.27524438
A446: Total Geral | B446: 219.94348

Sheet Sheet1
A1: id | B1: idLegislatura | C1: ultimoStatus.nome | D1: ultimoStatus.siglaPartido | E1: sexo | F1: dataNascimento | G1: escolaridade | H1: idade_posse | I1: tempo_atuacao_dias | J1: tempo_atuacao_percent | K1: mesa_1 | L1: mesa_2 | M1: pos_lider | N1: pos_comiss_pr | O1: relatorias | P1: relatorias_ln | Q1: mand_dep_estadual | R1: mand_ver | S1: mand_sen | T1: fid_municipais | U1: fid_gerais | V1: mesa_1_cum | W1: mesa_2_cum | X1: pos_lider_cum | Y1: pos_comiss_pr_cum | Z1: fid_municipais_cum | AA1: fid_gerais_cum | AB1: relatorias_cum | AC1: tempo_atuacao_percent_cum | AD1: mand_dep_estadual_cum | AE1: mand_ver_cum | AF1: mand_sen_cum | AG1: relatorias_ln_cum | AH1: idade_posse_norm | AI1: mesa_1_cum_norm | AJ1: mesa_2_cum_norm | AK1: pos_lider_cum_norm | AL1: pos_comiss_pr_cum_norm | AM1: fid_municipais_cum_norm | AN1: fid_gerais_cum_norm | AO1: tempo_atuacao_percent_cum_norm | AP1: mand_dep_estadual_cum_norm | AQ1: mand_ver_cum_norm | AR1: mand_sen_cum_norm | AS1: relatorias_ln_cum_norm | AT1: w_idade_posse_norm | AU1: w_tempo_atuacao_percent_cum_norm | AV1: w_mesa_1_cum_norm | AW1: w_mesa_2_cum_norm | AX1: w_pos_lider_cum_norm | AY1: w_pos_comiss_pr_cum_norm | AZ1: w_relatorias_ln_cum_norm | BA1: w_mand_dep_estadual_cum_norm | BB1: w_mand_ver_cum_norm | BC1: w_mand_sen_cum_norm | BD1: w_fid_municipais_cum_norm | BE1: w_fid_gerais_cum_norm | BF1: dim_comprometimento | BG1: dim_carreira | BH1: dim_fidelidade | BI1: dim_comprometimento_norm | BJ1: dim_carreira_norm | BK1: dim_fidelidade_norm | BL1: ipp | BM1: is_evangelico | BN1: matched_ID
A2: 204362 | B2: 56 | C2: Ricardo Guidi | D2: PL | E2: M | F2: 1977-09-28 | G2: Pós-Graduação | H2: 41 | I2: 1460 | J2: 1 | K2: 0 | L2: 0 | M2: 0 | N2: 0 | O2: 3 | P2: 1.0986123 | Q2: 1 | R2: 0 | S2: 0 | T2: 1 | U2: 1 | V2: 0 | W2: 0 | X2: 0 | Y2: 0 | Z2: 1 | AA2: 1 | AB2: 3 | AC2: 1 | AD2: 1 | AE2: 0 | AF2: 0 | AG2: 1.3862944 | AH2: 0.5060241 | AI2: 0 | AJ2: 0 | AK2: 0 | AL2: 0 | AM2: 0.11111111 | AN2: 0.14285714 | AO2: 0.94339623 | AP2: 0.14285714 | AQ2: 0 | AR2: 0 | AS2: 0.15160013 | AT2: 0.5060241 | AU2: 0.94339623 | AV2: 0 | AW2: 0 | AX2: 0 | AY2: 0 | AZ2: 0.30320025 | BA2: 0.028571429 | BB2: 0 | BC2: 0 | BD2: 0.11111111 | BE2: 0.14285714 | BF2: 1.2465965 | BG2: 0.53459552 | BH2: 0.25396825 | BI2: 0.12445212 | BJ2: 0.52842601 | BK2: 0.12698413 | BL2: 0.25995408 | BM2: TRUE | BN2: 228941
A3: 204362 | B3: 57 | C3: Ricardo Guidi | D3: PL | E3: M | F3: 1977-09-28 | G3: Pós-Graduação | H3: 41 | I3: 212 | J3: 0.37 | K3: 0 | L3: 0 | M3: 0 | N3: 0 | O3: 0 | P3: 0 | Q3: 1 | R3: 0 | S3: 0 | T3: 1 | U3: 0 | V3: 0 | W3: 0 | X3: 0 | Y3: 0 | Z3: 2 | AA3: 1 | AB3: 3 | AC3: 0.685 | AD3: 1 | AE3: 0 | AF3: 0 | AG3: 1.3862944 | AH3: 0.5060241 | AI3: 0 | AJ3: 0 | AK3: 0 | AL3: 0 | AM3: 0.22222222 | AN3: 0.14285714 | AO3: 0.64622642 | AP3: 0.14285714 | AQ3: 0 | AR3: 0 | AS3: 0.15160013 | AT3: 0.5060241 | AU3: 0.64622642 | AV3: 0 | AW3: 0 | AX3: 0 | AY3: 0 | AZ3: 0.30320025 | BA3: 0.028571429 | BB3: 0 | BC3: 0 | BD3: 0.22222222 | BE3: 0.14285714 | BF3: 0.94942667 | BG3: 0.53459552 | BH3: 0.36507937 | BI3: 0.094784611 | BJ3: 0.52842601 | BK3: 0.18253968 | BL3: 0.26858343 | BM3: TRUE | BN3: 228941
A4: 178954 | B4: 55 | C4: Lucio Mosquini | D4: MDB | E4: M | F4: 1969-07-23 | G4: Pós-Graduação | H4: 45 | I4: 1460 | J4: 1 | K4: 0 | L4: 0 | M4: 0 | N4: 0 | O4: 13 | P4: 2.5649494 | Q4: 0 | R4: 0 | S4: 0 | T4: 1 | U4: 1 | V4: 0 | W4: 0 | X4: 0 | Y4: 0 | Z4: 1 | AA4: 1 | AB4: 13 | AC4: 1 | AD4: 0 | AE4: 0 | AF4: 0 | AG4: 2.6390573 | AH4: 0.45783133 | AI4: 0 | AJ4: 0 | AK4: 0 | AL4: 0 | AM4: 0.11111111 | AN4: 0.14285714 | AO4: 0.94339623 | AP4: 0 | AQ4: 0 | AR4: 0 | AS4: 0.28859775 | AT4: 0.45783133 | AU4: 0.94339623 | AV4: 0 | AW4: 0 | AX4: 0 | AY4: 0 | AZ4: 0.57719549 | BA4: 0 | BB4: 0 | BC4: 0 | BD4: 0.11111111 | BE4: 0.14285714 | BF4: 1.5205917 | BG4: 0.45783133 | BH4: 0.25396825 | BI4: 0.15180603 | BJ4: 0.45254771 | BK4: 0.12698413 | BL4: 0.24377929 | BM4: TRUE | BN4: 228837
A5: 178954 | B5: 56 | C5: Lucio Mosquini | D5: MDB | E5: M | F5: 1969-07-23 | G5: Pós-Graduação | H5: 45 | I5: 1460 | J5: 1 | K5: 0 | L5: 0 | M5: 0 | N5: 0 | O5: 14 | P5: 2.6390573 | Q5: 0 | R5: 0 | S5: 0 | T5: 1 | U5: 1 | V5: 0 | W5: 0 | X5: 0 | Y5: 0 | Z5: 2 | AA5: 2 | AB5: 27 | AC5: 1 | AD5: 0 | AE5: 0 | AF5: 0 | AG5: 3.3322045 | AH5: 0.45783133 | AI5: 0 | AJ5: 0 | AK5: 0 | AL5: 0 | AM5: 0.22222222 | AN5: 0.28571429 | AO5: 0.94339623 | AP5: 0 | AQ5: 0 | AR5: 0 | AS5: 0.36439781 | AT5: 0.45783133 | AU5: 0.94339623 | AV5: 0 | AW5: 0 | AX5: 0 | AY5: 0 | AZ5: 0.72879562 | BA5: 0 | BB5: 0 | BC5: 0 | BD5: 0.22222222 | BE5: 0.28571429 | BF5: 1.6721918 | BG5: 0.45783133 | BH5: 0.50793651 | BI5: 0.16694081 | BJ5: 0.45254771 | BK5: 0.25396825 | BL5: 0.29115226 | BM5: TRUE | BN5: 228837
A6: 178954 | B6: 57 | C6: Lucio Mosquini | D6: MDB | E6: M | F6: 1969-07-23 | G6: Pós-Graduação | H6: 45 | I6: 603 | J6: 1.06 | K6: 0 | L6: 1 | M6: 0 | N6: 0 | O6: 0 | P6: 0 | Q6: 0 | R6: 0 | S6: 0 | T6: 1 | U6: 0 | V6: 0 | W6: 1 | X6: 0 | Y6: 0 | Z6: 3 | AA6: 2 | AB6: 27 | AC6: 1.02 | AD6: 0 | AE6: 0 | AF6: 0 | AG6: 3.3322045 | AH6: 0.45783133 | AI6: 0 | AJ6: 0.2 | AK6: 0 | AL6: 0 | AM6: 0.33333333 | AN6: 0.28571429 | AO6: 0.96226415 | AP6: 0 | AQ6: 0 | AR6: 0 | AS6: 0.36439781 | AT6: 0.45783133 | AU6: 0.96226415 | AV6: 0 | AW6: 0.6 | AX6: 0 | AY6: 0 | AZ6: 0.72879562 | BA6: 0 | BB6: 0 | BC6: 0 | BD6: 0.33333333 | BE6: 0.28571429 | BF6: 2.2910598 | BG6: 0.45783133 | BH6: 0.61904762 | BI6: 0.22872457 | BJ6: 0.45254771 | BK6: 0.30952381 | BL6: 0.33026536 | BM6: TRUE | BN6: 228837
A7: 139178 | B7: 48 | C7: DASO COIMBRA | D7: PRN | E7: M | F7: 1926-06-16 | G7: Superior | H7: 60 | I7: 1460 | J7: 1 | K7: 0 | L7: 0 | M7: 0 | N7: 0 | O7: 0 | P7: 0 | Q7: 2 | R7: 0 | S7: 0 | T7: 1 | U7: 0 | V7: 0 | W7: 0 | X7: 0 | Y7: 0 | Z7: 1 | AA7: 0 | AB7: 0 | AC7: 1 | AD7: 2 | AE7: 0 | AF7: 0 | AG7: 0 | AH7: 0.27710843 | AI7: 0 | AJ7: 0 | AK7: 0 | AL7: 0 | AM7: 0.11111111 | AN7: 0 | AO7: 0.94339623 | AP7: 0.28571429 | AQ7: 0 | AR7: 0 | AS7: 0 | AT7: 0.27710843 | AU7: 0.94339623 | AV7: 0 | AW7: 0 | AX7: 0 | AY7: 0 | AZ7: 0 | BA7: 0.057142857 | BB7: 0 | BC7: 0 | BD7: 0.11111111 | BE7: 0 | BF7: 0.94339623 | BG7: 0.33425129 | BH7: 0.11111111 | BI7: 0.09418257 | BJ7: 0.33039385 | BK7: 0.055555556 | BL7: 0.16004399 | BM7: TRUE | BN7: 228616
A8: 204573 | B8: 56 | C8: Otto Alencar Filho | D8: PSD | E8: M | F8: 1977-07-07 | G8: Pós-Graduação | H8: 41 | I8: 1460 | J8: 1 | K8: 0 | L8: 0 | M8: 0 | N8: 0 | O8: 41 | P8: 3.7135721 | Q8: 0 | R8: 0 | S8: 0 | T8: 1 | U8: 1 | V8: 0 | W8: 0 | X8: 0 | Y8: 0 | Z8: 1 | AA8: 1 | AB8: 41 | AC8: 1 | AD8: 0 | AE8: 0 | AF8: 0 | AG8: 3.7376696 | AH8: 0.5060241 | AI8: 0 | AJ8: 0 | AK8: 0 | AL8: 0 | AM8: 0.11111111 | AN8: 0.14285714 | AO8: 0.94339623 | AP8: 0 | AQ8: 0 | AR8: 0 | AS8: 0.408738 | AT8: 0.5060241 | AU8: 0.94339623 | AV8: 0 | AW8: 0 | AX8: 0 | AY8: 0 | AZ8: 0.81747601 | BA8: 0 | BB8: 0 | BC8: 0 | BD8: 0.11111111 | BE8: 0.14285714 | BF8: 1.7608722 | BG8: 0.5060241 | BH8: 0.25396825 | BI8: 0.17579408 | BJ8: 0.50018431 | BK8: 0.12698413 | BL8: 0.26765417 | BM8: TRUE | BN8: 228042
A9: 204573 | B9: 57 | C9: Otto Alencar Filho | D9: PSD | E9: M | F9: 1977-07-07 | G9: Pós-Graduação | H9: 41 | I9: 603 | J9: 1.06 | K9: 0 | L9: 0 | M9: 0 | N9: 0 | O9: 7 | P9: 1.9459101 | Q9: 0 | R9: 0 | S9: 0 | T9: 1 | U9: 0 | V9: 0 | W9: 0 | X9: 0 | Y9: 0 | Z9: 2 | AA9: 1 | AB9: 48 | AC9: 1.03 | AD9: 0 | AE9: 0 | AF9: 0 | AG9: 3.8918203 | AH9: 0.5060241 | AI9: 0 | AJ9: 0 | AK9: 0 | AL9: 0 | AM9: 0.22222222 | AN9: 0.14285714 | AO9: 0.97169811 | AP9: 0 | AQ9: 0 | AR9: 0 | AS9: 0.42559536 | AT9: 0.5060241 | AU9: 0.97169811 | AV9: 0 | AW9: 0 | AX9: 0 | AY9: 0 | AZ9: 0.85119073 | BA9: 0 | BB9: 0 | BC9: 0 | BD9: 0.22222222 | BE9: 0.14285714 | BF9: 1.8228888 | BG9: 0.5060241 | BH9: 0.36507937 | BI9: 0.18198542 | BJ9: 0.50018431 | BK9: 0.18253968 | BL9: 0.28823647 | BM9: TRUE | BN9: 228042
A10: 139284 | B10: 48 | C10: LEVY DIAS | D10: PFL | E10: M | F10: 1938-05-30 | G10: Superior | H10: 48 | I10: 1460 | J10: 1 | K10: 0 | L10: 0 | M10: 0 | N10: 0 | O10: 0 | P10: 0 | Q10: 1 | R10: 0 | S10: 0 | T10: 1 | U10: 0 | V10: 0 | W10: 0 | X10: 0 | Y10: 0 | Z10: 1 | AA10: 0 | AB10: 0 | AC10: 1 | AD10: 1 | AE10: 0 | AF10: 0 | AG10: 0 | AH10: 0.42168675 | AI10: 0 | AJ10: 0 | AK10: 0 | AL10: 0 | AM10: 0.11111111 | AN10: 0 | AO10: 0.94339623 | AP10: 0.14285714 | AQ10: 0 | AR10: 0 | AS10: 0 | AT10: 0.42168675 | AU10: 0.94339623 | AV10: 0 | AW10: 0 | AX10: 0 | AY10: 0 | AZ10: 0 | BA10: 0.028571429 | BB10: 0 | BC10: 0 | BD10: 0.11111111 | BE10: 0 | BF10: 0.94339623 | BG10: 0.45025818 | BH10: 0.11111111 | BI10: 0.09418257 | BJ10: 0.44506196 | BK10: 0.055555556 | BL10: 0.19826669 | BM10: TRUE | BN10: 227660
A11: 220534 | B11: 57 | C11: Fred Linhares | D11: REPUBLICANOS | E11: M | F11: 1980-01-26 | G11: Superior | H11: 43 | I11: 603 | J11: 1.06 | K11: 0 | L11: 0 | M11: 0 | N11: 0 | O11: 19 | P11: 2.944439 | Q11: 0 | R11: 0 | S11: 0 | T11: 1 | U11: 0 | V11: 0 | W11: 0 | X11: 0 | Y11: 0 | Z11: 1 | AA11: 0 | AB11: 19 | AC11: 1.06 | AD11: 0 | AE11: 0 | AF11: 0 | AG11: 2.9957323 | AH11: 0.48192771 | AI11: 0 | AJ11: 0 | AK11: 0 | AL11: 0 | AM11: 0.11111111 | AN11: 0 | AO11: 1 | AP11: 0 | AQ11: 0 | AR11: 0 | AS11: 0.32760242 | AT11: 0.48192771 | AU11: 1 | AV11: 0 | AW11: 0 | AX11: 0 | AY11: 0 | AZ11: 0.65520485 | BA11: 0 | BB11: 0 | BC11: 0 | BD11: 0.11111111 | BE11: 0 | BF11: 1.6552048 | BG11: 0.48192771 | BH11: 0.11111111 | BI11: 0.16524493 | BJ11: 0.47636601 | BK11: 0.055555556 | BL11: 0.23238883 | BM11: TRUE | BN11: 225727
A12: 139168 | B12: 48 | C12: CELSO DOURADO | D12: PMDB | E12: M | F12: 1932-06-10 | G12: Superior | H12: 54 | I12: 1460 | J12: 1 | K12: 0 | L12: 0 | M12: 0 | N12: 0 | O12: 0 | P12: 0 | Q12: 0 | R12: 1 | S12: 0 | T12: 1 | U12: 0 | V12: 0 | W12: 0 | X12: 0 | Y12: 0 | Z12: 1 | AA12: 0 | AB12: 0 | AC12: 1 | AD12: 0 | AE12: 1 | AF12: 0 | AG12: 0 | AH12: 0.34939759 | AI12: 0 | AJ12: 0 | AK12: 0 | AL12: 0 | AM12: 0.11111111 | AN12: 0 | AO12: 0.94339623 | AP12: 0 | AQ12: 0.16666667 | AR12: 0 | AS12: 0 | AT12: 0.34939759 | AU12: 0.94339623 | AV12: 0 | AW12: 0 | AX12: 0 | AY12: 0 | AZ12: 0 | BA12: 0 | BB12: 0.016666667 | BC12: 0 | BD12: 0.11111111 | BE12: 0 | BF12: 0.94339623 | BG12: 0.36606426 | BH12: 0.11111111 | BI12: 0.09418257 | BJ12: 0.36183968 | BK12: 0.055555556 | BL12: 0.17052594 | BM12: TRUE | BN12: 221339
A13: 160629 | B13: 54 | C13: Romero Rodrigues | D13: PODE | E13: M | F13: 1966-01-09 | G13: Mestrado | H13: 45 | I13: 579 | J13: 0.4 | K13: 0 | L13: 0 | M13: 0 | N13: 0 | O13: 16 | P13: 2.7725887 | Q13: 1 | R13: 4 | S13: 0 | T13: 0 | U13: 0 | V13: 0 | W13: 0 | X13: 0 | Y13: 0 | Z13: 0 | AA13: 0 | AB13: 16 | AC13: 0.4 | AD13: 1 | AE13: 4 | AF13: 0 | AG13: 2.8332133 | AH13: 0.45783133 | AI13: 0 | AJ13: 0 | AK13: 0 | AL13: 0 | AM13: 0 | AN13: 0 | AO13: 0.37735849 | AP13: 0.14285714 | AQ13: 0.66666667 | AR13: 0 | AS13: 0.30982994 | AT13: 0.45783133 | AU13: 0.37735849 | AV13: 0 | AW13: 0 | AX13: 0 | AY13: 0 | AZ13: 0.61965989 | BA13: 0.028571429 | BB13: 0.066666667 | BC13: 0 | BD13: 0 | BE13: 0 | BF13: 0.99701838 | BG13: 0.55306942 | BH13: 0 | BI13: 0.099535859 | BJ13: 0.5466867 | BK13: 0 | BL13: 0.21540752 | BM13: TRUE | BN13: 221183
... A92: 220532 | B92: 57 | C92: Rafael Prudente | D92: MDB | E92: M | F92: 1983-11-05 | G92: Superior | H92: 39 | I92: 603 | J92: 1.06 | K92: 0 | L92: 0 | M92: 0 | N92: 1 | O92: 4 | P92: 1.3862944 | Q92: 0 | R92: 0 | S92: 0 | T92: 1 | U92: 0 | V92: 0 | W92: 0 | X92: 0 | Y92: 1 | Z92: 1 | AA92: 0 | AB92: 4 | AC92: 1.06 | AD92: 0 | AE92: 0 | AF92: 0 | AG92: 1.6094379 | AH92: 0.53012048 | AI92: 0 | AJ92: 0 | AK92: 0 | AL92: 0.2 | AM92: 0.11111111 | AN92: 0 | AO92: 1 | AP92: 0 | AQ92: 0 | AR92: 0 | AS92: 0.1760023 | AT92: 0.53012048 | AU92: 1 | AV92: 0 | AW92: 0 | AX92: 0 | AY92: 0.6 | AZ92: 0.3520046 | BA92: 0 | BB92: 0 | BC92: 0 | BD92: 0.11111111 | BE92: 0 | BF92: 1.9520046 | BG92: 0.53012048 | BH92: 0.11111111 | BI92: 0.1948755 | BJ92: 0.52400261 | BK92: 0.055555556 | BL92: 0.25814455 | BM92: TRUE | BN92: 204550
A93: 220619 | B93: 57 | C93: Delegado Ramagem | D93: PL | E93: M | F93: 1972-05-08 | G93: 0 | H93: 50 | I93: 603 | J93: 1.06 | K93: 0 | L93: 0 | M93: 0 | N93: 0 | O93: 34 | P93: 3.5263605 | Q93: 0 | R93: 0 | S93: 0 | T93: 1 | U93: 0 | V93: 0 | W93: 0 | X93: 0 | Y93: 0 | Z93: 1 | AA93: 0 | AB93: 34 | AC93: 1.06 | AD93: 0 | AE93: 0 | AF93: 0 | AG93: 3.5553481 | AH93: 0.39759036 | AI93: 0 | AJ93: 0 | AK93: 0 | AL93: 0 | AM93: 0.11111111 | AN93: 0 | AO93: 1 | AP93: 0 | AQ93: 0 | AR93: 0 | AS93: 0.38879998 | AT93: 0.39759036 | AU93: 1 | AV93: 0 | AW93: 0 | AX93: 0 | AY93: 0 | AZ93: 0.77759996 | BA93: 0 | BB93: 0 | BC93: 0 | BD93: 0.11111111 | BE93: 0 | BF93: 1.7776 | BG93: 0.39759036 | BH93: 0.11111111 | BI93: 0.17746407 | BJ93: 0.39300196 | BK93: 0.055555556 | BL93: 0.20867386 | BM93: TRUE | BN93: 204537
A94: 215043 | B94: 56 | C94: Josivaldo JP | D94: PSD | E94: M | F94: 1983-11-29 | G94: Ensino Médio | H94: 35 | I94: 760 | J94: 0.52 | K94: 0 | L94: 0 | M94: 0 | N94: 0 | O94: 12 | P94: 2.4849066 | Q94: 0 | R94: 0 | S94: 0 | T94: 1 | U94: 1 | V94: 0 | W94: 0 | X94: 0 | Y94: 0 | Z94: 1 | AA94: 1 | AB94: 12 | AC94: 0.52 | AD94: 0 | AE94: 0 | AF94: 0 | AG94: 2.5649494 | AH94: 0.57831325 | AI94: 0 | AJ94: 0 | AK94: 0 | AL94: 0 | AM94: 0.11111111 | AN94: 0.14285714 | AO94: 0.49056604 | AP94: 0 | AQ94: 0 | AR94: 0 | AS94: 0.28049357 | AT94: 0.57831325 | AU94: 0.49056604 | AV94: 0 | AW94: 0 | AX94: 0 | AY94: 0 | AZ94: 0.56098713 | BA94: 0 | BB94: 0 | BC94: 0 | BD94: 0.11111111 | BE94: 0.14285714 | BF94: 1.0515532 | BG94: 0.57831325 | BH94: 0.25396825 | BI94: 0.10498026 | BJ94: 0.57163921 | BK94: 0.12698413 | BL94: 0.26786787 | BM94: TRUE | BN94: 204534
A95: 215043 | B95: 57 | C95: Josivaldo JP | D95: PSD | E95: M | F95: 1983-11-29 | G95: Ensino Médio | H95: 35 | I95: 603 | J95: 1.06 | K95: 0 | L95: 0 | M95: 0 | N95: 0 | O95: 1 | P95: 0 | Q95: 0 | R95: 0 | S95: 0 | T95: 1 | U95: 0 | V95: 0 | W95: 0 | X95: 0 | Y95: 0 | Z95: 2 | AA95: 1 | AB95: 13 | AC95: 0.79 | AD95: 0 | AE95: 0 | AF95: 0 | AG95: 2.6390573 | AH95: 0.57831325 | AI95: 0 | AJ95: 0 | AK95: 0 | AL95: 0 | AM95: 0.22222222 | AN95: 0.14285714 | AO95: 0.74528302 | AP95: 0 | AQ95: 0 | AR95: 0 | AS95: 0.28859775 | AT95: 0.57831325 | AU95: 0.74528302 | AV95: 0 | AW95: 0 | AX95: 0 | AY95: 0 | AZ95: 0.57719549 | BA95: 0 | BB95: 0 | BC95: 0 | BD95: 0.22222222 | BE95: 0.14285714 | BF95: 1.3224785 | BG95: 0.57831325 | BH95: 0.36507937 | BI95: 0.13202769 | BJ95: 0.57163921 | BK95: 0.18253968 | BL95: 0.29540219 | BM95: TRUE | BN95: 204534
A96: 178876 | B96: 55 | C96: Célio Silveira | D96: MDB | E96: M | F96: 1959-09-19 | G96: Superior | H96: 55 | I96: 1460 | J96: 1 | K96: 0 | L96: 0 | M96: 0 | N96: 0 | O96: 14 | P96: 2.6390573 | Q96: 2 | R96: 0 | S96: 0 | T96: 1 | U96: 1 | V96: 0 | W96: 0 | X96: 0 | Y96: 0 | Z96: 1 | AA96: 1 | AB96: 14 | AC96: 1 | AD96: 2 | AE96: 0 | AF96: 0 | AG96: 2.7080502 | AH96: 0.3373494 | AI96: 0 | AJ96: 0 | AK96: 0 | AL96: 0 | AM96: 0.11111111 | AN96: 0.14285714 | AO96: 0.94339623 | AP96: 0.28571429 | AQ96: 0 | AR96: 0 | AS96: 0.29614256 | AT96: 0.3373494 | AU96: 0.94339623 | AV96: 0 | AW96: 0 | AX96: 0 | AY96: 0 | AZ96: 0.59228511 | BA96: 0.057142857 | BB96: 0 | BC96: 0 | BD96: 0.11111111 | BE96: 0.14285714 | BF96: 1.5356813 | BG96: 0.39449225 | BH96: 0.25396825 | BI96: 0.15331248 | BJ96: 0.3899396 | BK96: 0.12698413 | BL96: 0.22341207 | BM96: TRUE | BN96: 204521
A97: 178876 | B97: 56 | C97: Célio Silveira | D97: MDB | E97: M | F97: 1959-09-19 | G97: Superior | H97: 55 | I97: 1460 | J97: 1 | K97: 0 | L97: 0 | M97: 0 | N97: 0 | O97: 35 | P97: 3.5553481 | Q97: 2 | R97: 0 | S97: 0 | T97: 1 | U97: 1 | V97: 0 | W97: 0 | X97: 0 | Y97: 0 | Z97: 2 | AA97: 2 | AB97: 49 | AC97: 1 | AD97: 2 | AE97: 0 | AF97: 0 | AG97: 3.912023 | AH97: 0.3373494 | AI97: 0 | AJ97: 0 | AK97: 0 | AL97: 0 | AM97: 0.22222222 | AN97: 0.28571429 | AO97: 0.94339623 | AP97: 0.28571429 | AQ97: 0 | AR97: 0 | AS97: 0.42780466 | AT97: 0.3373494 | AU97: 0.94339623 | AV97: 0 | AW97: 0 | AX97: 0 | AY97: 0 | AZ97: 0.85560932 | BA97: 0.057142857 | BB97: 0 | BC97: 0 | BD97: 0.22222222 | BE97: 0.28571429 | BF97: 1.7990055 | BG97: 0.39449225 | BH97: 0.50793651 | BI97: 0.17960106 | BJ97: 0.3899396 | BK97: 0.25396825 | BL97: 0.27450297 | BM97: TRUE | BN97: 204521
A98: 178876 | B98: 57 | C98: Célio Silveira | D98: MDB | E98: M | F98: 1959-09-19 | G98: Superior | H98: 55 | I98: 478 | J98: 0.84 | K98: 0 | L98: 0 | M98: 0 | N98: 0 | O98: 11 | P98: 2.3978953 | Q98: 2 | R98: 0 | S98: 0 | T98: 1 | U98: 0 | V98: 0 | W98: 0 | X98: 0 | Y98: 0 | Z98: 3 | AA98: 2 | AB98: 60 | AC98: 0.94666667 | AD98: 2 | AE98: 0 | AF98: 0 | AG98: 4.1108739 | AH98: 0.3373494 | AI98: 0 | AJ98: 0 | AK98: 0 | AL98: 0 | AM98: 0.33333333 | AN98: 0.28571429 | AO98: 0.89308176 | AP98: 0.28571429 | AQ98: 0 | AR98: 0 | AS98: 0.44955027 | AT98: 0.3373494 | AU98: 0.89308176 | AV98: 0 | AW98: 0 | AX98: 0 | AY98: 0 | AZ98: 0.89910054 | BA98: 0.057142857 | BB98: 0 | BC98: 0 | BD98: 0.33333333 | BE98: 0.28571429 | BF98: 1.7921823 | BG98: 0.39449225 | BH98: 0.61904762 | BI98: 0.17891988 | BJ98: 0.3899396 | BK98: 0.30952381 | BL98: 0.29279443 | BM98: FALSE | BN98: 204521
A99: 204388 | B99: 56 | C99: Bibo Nunes | D99: PL | E99: M | F99: 1957-01-09 | G99: Superior Incompleto | H99: 62 | I99: 1460 | J99: 1 | K99: 0 | L99: 0 | M99: 0 | N99: 1 | O99: 54 | P99: 3.988984 | Q99: 0 | R99: 1 | S99: 0 | T99: 1 | U99: 1 | V99: 0 | W99: 0 | X99: 0 | Y99: 1 | Z99: 1 | AA99: 1 | AB99: 54 | AC99: 1 | AD99: 0 | AE99: 1 | AF99: 0 | AG99: 4.0073332 | AH99: 0.25301205 | AI99: 0 | AJ99: 0 | AK99: 0 | AL99: 0.2 | AM99: 0.11111111 | AN99: 0.14285714 | AO99: 0.94339623 | AP99: 0 | AQ99: 0.16666667 | AR99: 0 | AS99: 0.43822743 | AT99: 0.25301205 | AU99: 0.94339623 | AV99: 0 | AW99: 0 | AX99: 0 | AY99: 0.6 | AZ99: 0.87645487 | BA99: 0 | BB99: 0.016666667 | BC99: 0 | BD99: 0.11111111 | BE99: 0.14285714 | BF99: 2.4198511 | BG99: 0.26967871 | BH99: 0.25396825 | BI99: 0.24158226 | BJ99: 0.26656648 | BK99: 0.12698413 | BL99: 0.21171096 | BM99: TRUE | BN99: 204519
A100: 204388 | B100: 57 | C100: Bibo Nunes | D100: PL | E100: M | F100: 1957-01-09 | G100: Superior Incompleto | H100: 62 | I100: 603 | J100: 1.06 | K100: 0 | L100: 0 | M100: 0 | N100: 0 | O100: 35 | P100: 3.5553481 | Q100: 0 | R100: 1 | S100: 0 | T100: 1 | U100: 0 | V100: 0 | W100: 0 | X100: 0 | Y100: 1 | Z100: 2 | AA100: 1 | AB100: 89 | AC100: 1.03 | AD100: 0 | AE100: 1 | AF100: 0 | AG100: 4.4998097 | AH100: 0.25301205 | AI100: 0 | AJ100: 0 | AK100: 0 | AL100: 0.2 | AM100: 0.22222222 | AN100: 0.14285714 | AO100: 0.97169811 | AP100: 0 | AQ100: 0.16666667 | AR100: 0 | AS100: 0.49208288 | AT100: 0.25301205 | AU100: 0.97169811 | AV100: 0 | AW100: 0 | AX100: 0 | AY100: 0.6 | AZ100: 0.98416576 | BA100: 0 | BB100: 0.016666667 | BC100: 0 | BD100: 0.22222222 | BE100: 0.14285714 | BF100: 2.5558639 | BG100: 0.26967871 | BH100: 0.36507937 | BI100: 0.2551609 | BJ100: 0.26656648 | BK100: 0.18253968 | BL100: 0.23475569 | BM100: TRUE | BN100: 204519
A101: 141540 | B101: 53 | C101: DR. NECHAR | D101: PP** | E101: M | F101: 1951-06-26 | G101: Superior | H101: 55 | I101: 1460 | J101: 1 | K101: 0 | L101: 0 | M101: 0 | N101: 0 | O101: 58 | P101: 4.060443 | Q101: 0 | R101: 1 | S101: 0 | T101: 1 | U101: 1 | V101: 0 | W101: 0 | X101: 0 | Y101: 0 | Z101: 1 | AA101: 1 | AB101: 58 | AC101: 1 | AD101: 0 | AE101: 1 | AF101: 0 | AG101: 4.0775374 | AH101: 0.3373494 | AI101: 0 | AJ101: 0 | AK101: 0 | AL101: 0 | AM101: 0.11111111 | AN101: 0.14285714 | AO101: 0.94339623 | AP101: 0 | AQ101: 0.16666667 | AR101: 0 | AS101: 0.44590472 | AT101: 0.3373494 | AU101: 0.94339623 | AV101: 0 | AW101: 0 | AX101: 0 | AY101: 0 | AZ101: 0.89180944 | BA101: 0 | BB101: 0.016666667 | BC101: 0 | BD101: 0.11111111 | BE101: 0.14285714 | BF101: 1.8352057 | BG101: 0.35401606 | BH101: 0.25396825 | BI101: 0.18321505 | BJ101: 0.34993053 | BK101: 0.12698413 | BL101: 0.22004324 | BM101: TRUE | BN101: 204501
A102: 74259 | B102: 52 | C102: VIEIRA REIS | D102: S.PART. | E102: M | F102: 1959-07-06 | G102: Superior | H102: 43 | I102: 1460 | J102: 1 | K102: 0 | L102: 0 | M102: 0 | N102: 0 | O102: 23 | P102: 3.1354942 | Q102: 0 | R102: 0 | S102: 0 | T102: 1 | U102: 0 | V102: 0 | W102: 0 | X102: 0 | Y102: 0 | Z102: 1 | AA102: 0 | AB102: 23 | AC102: 1 | AD102: 0 | AE102: 0 | AF102: 0 | AG102: 3.1780538 | AH102: 0.48192771 | AI102: 0 | AJ102: 0 | AK102: 0 | AL102: 0 | AM102: 0.11111111 | AN102: 0 | AO102: 0.94339623 | AP102: 0 | AQ102: 0 | AR102: 0 | AS102: 0.34754045 | AT102: 0.48192771 | AU102: 0.94339623 | AV102: 0 | AW102: 0 | AX102: 0 | AY102: 0 | AZ102: 0.6950809 | BA102: 0 | BB102: 0 | BC102: 0 | BD102: 0.11111111 | BE102: 0 | BF102: 1.6384771 | BG102: 0.48192771 | BH102: 0.11111111 | BI102: 0.16357495 | BJ102: 0.47636601 | BK102: 0.055555556 | BL102: 0.23183217 | BM102: TRUE | BN102: 204485
A103: 220556 | B103: 57 | C103: Ana Paula Lima | D103: PT | E103: F | F103: 1964-04-19 | G103: Superior | H103: 58 | I103: 603 | J103: 1.06 | K103: 0 | L103: 0 | M103: 0 | N103: 0 | O103: 34 | P103: 3.5263605 | Q103: 1 | R103: 0 | S103: 0 | T103: 1 | U103: 0 | V103: 0 | W103: 0 | X103: 0 | Y103: 0 | Z103: 1 | AA103: 0 | AB103: 34 | AC103: 1.06 | AD103: 1 | AE103: 0 | AF103: 0 | AG103: 3.5553481 | AH103: 0.30120482 | AI103: 0 | AJ103: 0 | AK103: 0 | AL103: 0 | AM103: 0.11111111 | AN103: 0 | AO103: 1 | AP103: 0.14285714 | AQ103: 0 | AR103: 0 | AS103: 0.38879998 | AT103: 0.30120482 | AU103: 1 | AV103: 0 | AW103: 0 | AX103: 0 | AY103: 0 | AZ103: 0.77759996 | BA103: 0.028571429 | BB103: 0 | BC103: 0 | BD103: 0.11111111 | BE103: 0 | BF103: 1.7776 | BG103: 0.32977625 | BH103: 0.11111111 | BI103: 0.17746407 | BJ103: 0.32597045 | BK103: 0.055555556 | BL103: 0.18633003 | BM103: TRUE | BN103: 204480
A104: 204529 | B104: 56 | C104: Policial Katia Sastre | D104: PL | E104: F | F104: 1976-04-04 | G104: Pós-Graduação | H104: 42 | I104: 1460 | J104: 1 | K104: 0 | L104: 0 | M104: 0 | N104: 1 | O104: 6 | P104: 1.7917595 | Q104: 0 | R104: 0 | S104: 0 | T104: 1 | U104: 1 | V104: 0 | W104: 0 | X104: 0 | Y104: 1 | Z104: 1 | AA104: 1 | AB104: 6 | AC104: 1 | AD104: 0 | AE104: 0 | AF104: 0 | AG104: 1.9459101 | AH104: 0.4939759 | AI104: 0 | AJ104: 0 | AK104: 0 | AL104: 0.2 | AM104: 0.11111111 | AN104: 0.14285714 | AO104: 0.94339623 | AP104: 0 | AQ104: 0 | AR104: 0 | AS104: 0.21279768 | AT104: 0.4939759 | AU104: 0.94339623 | AV104: 0 | AW104: 0 | AX104: 0 | AY104: 0.6 | AZ104: 0.42559536 | BA104: 0 | BB104: 0 | BC104: 0 | BD104: 0.11111111 | BE104: 0.14285714 | BF104: 1.9689916 | BG104: 0.4939759 | BH104: 0.25396825 | BI104: 0.19657137 | BJ104: 0.48827516 | BK104: 0.12698413 | BL104: 0.27061022 | BM104: TRUE | BN104: 204477
A105: 220583 | B105: 57 | C105: Delegado Fabio Costa | D105: PP | E105: M | F105: 1980-10-15 | G105: Pós-Graduação | H105: 42 | I105: 603 | J105: 1.06 | K105: 0 | L105: 0 | M105: 0 | N105: 0 | O105: 11 | P105: 2.3978953 | Q105: 0 | R105: 1 | S105: 0 | T105: 1 | U105: 0 | V105: 0 | W105: 0 | X105: 0 | Y105: 0 | Z105: 1 | AA105: 0 | AB105: 11 | AC105: 1.06 | AD105: 0 | AE105: 1 | AF105: 0 | AG105: 2.4849066 | AH105: 0.4939759 | AI105: 0 | AJ105: 0 | AK105: 0 | AL105: 0 | AM105: 0.11111111 | AN105: 0 | AO105: 1 | AP105: 0 | AQ105: 0.16666667 | AR105: 0 | AS105: 0.27174039 | AT105: 0.4939759 | AU105: 1 | AV105: 0 | AW105: 0 | AX105: 0 | AY105: 0 | AZ105: 0.54348077 | BA105: 0 | BB105: 0.016666667 | BC105: 0 | BD105: 0.11111111 | BE105: 0 | BF105: 1.5434808 | BG105: 0.51064257 | BH105: 0.11111111 | BI105: 0.15409113 | BJ105: 0.50474948 | BK105: 0.055555556 | BL105: 0.23813205 | BM105: TRUE | BN105: 204476
... A319: 74434 | B319: 52 | C319: SALATIEL CARVALHO | D319: PFL | E319: M | F319: 1954-04-05 | G319: Superior | H319: 32 | I319: 413 | J319: 0.28 | K319: 0 | L319: 0 | M319: 0 | N319: 0 | O319: 1 | P319: 0 | Q319: 0 | R319: 0 | S319: 0 | T319: 1 | U319: 1 | V319: 0 | W319: 0 | X319: 0 | Y319: 0 | Z319: 5 | AA319: 3 | AB319: 26 | AC319: 0.856 | AD319: 0 | AE319: 0 | AF319: 0 | AG319: 3.2958369 | AH319: 0.61445783 | AI319: 0 | AJ319: 0 | AK319: 0 | AL319: 0 | AM319: 0.55555556 | AN319: 0.42857143 | AO319: 0.80754717 | AP319: 0 | AQ319: 0 | AR319: 0 | AS319: 0.36042078 | AT319: 0.61445783 | AU319: 0.80754717 | AV319: 0 | AW319: 0 | AX319: 0 | AY319: 0 | AZ319: 0.72084155 | BA319: 0 | BB319: 0 | BC319: 0 | BD319: 0.55555556 | BE319: 0.42857143 | BF319: 1.5283887 | BG319: 0.61445783 | BH319: 0.98412698 | BI319: 0.15258443 | BJ319: 0.60736666 | BK319: 0.49206349 | BL319: 0.41733819 | BM319: TRUE | BN319: 141526
A320: 220590 | B320: 57 | C320: Coronel Ulysses | D320: UNIÃO | E320: M | F320: 1972-10-19 | G320: 0 | H320: 50 | I320: 603 | J320: 1.06 | K320: 0 | L320: 0 | M320: 0 | N320: 0 | O320: 10 | P320: 2.3025851 | Q320: 0 | R320: 0 | S320: 0 | T320: 1 | U320: 0 | V320: 0 | W320: 0 | X320: 0 | Y320: 0 | Z320: 1 | AA320: 0 | AB320: 10 | AC320: 1.06 | AD320: 0 | AE320: 0 | AF320: 0 | AG320: 2.3978953 | AH320: 0.39759036 | AI320: 0 | AJ320: 0 | AK320: 0 | AL320: 0 | AM320: 0.11111111 | AN320: 0 | AO320: 1 | AP320: 0 | AQ320: 0 | AR320: 0 | AS320: 0.26222514 | AT320: 0.39759036 | AU320: 1 | AV320: 0 | AW320: 0 | AX320: 0 | AY320: 0 | AZ320: 0.52445027 | BA320: 0 | BB320: 0 | BC320: 0 | BD320: 0.11111111 | BE320: 0 | BF320: 1.5244503 | BG320: 0.39759036 | BH320: 0.11111111 | BI320: 0.15219124 | BJ320: 0.39300196 | BK320: 0.055555556 | BL320: 0.20024959 | BM320: TRUE | BN320: 141513
A321: 74144 | B321: 52 | C321: ZELINDA NOVAES | D321: PFL | E321: F | F321: 1944-12-25 | G321: Superior | H321: 58 | I321: 1460 | J321: 1 | K321: 0 | L321: 0 | M321: 0 | N321: 0 | O321: 27 | P321: 3.2958369 | Q321: 3 | R321: 0 | S321: 0 | T321: 1 | U321: 0 | V321: 0 | W321: 0 | X321: 0 | Y321: 0 | Z321: 1 | AA321: 0 | AB321: 27 | AC321: 1 | AD321: 3 | AE321: 0 | AF321: 0 | AG321: 3.3322045 | AH321: 0.30120482 | AI321: 0 | AJ321: 0 | AK321: 0 | AL321: 0 | AM321: 0.11111111 | AN321: 0 | AO321: 0.94339623 | AP321: 0.42857143 | AQ321: 0 | AR321: 0 | AS321: 0.36439781 | AT321: 0.30120482 | AU321: 0.94339623 | AV321: 0 | AW321: 0 | AX321: 0 | AY321: 0 | AZ321: 0.72879562 | BA321: 0.085714286 | BB321: 0 | BC321: 0 | BD321: 0.11111111 | BE321: 0 | BF321: 1.6721918 | BG321: 0.3869191 | BH321: 0.11111111 | BI321: 0.16694081 | BJ321: 0.38245385 | BK321: 0.055555556 | BL321: 0.20165007 | BM321: TRUE | BN321: 141511
A322: 178927 | B322: 55 | C322: Aliel Machado | D322: PV | E322: M | F322: 1989-02-26 | G322: Superior Incompleto | H322: 25 | I322: 1460 | J322: 1 | K322: 0 | L322: 0 | M322: 0 | N322: 0 | O322: 18 | P322: 2.8903718 | Q322: 0 | R322: 1 | S322: 0 | T322: 0 | U322: 1 | V322: 0 | W322: 0 | X322: 0 | Y322: 0 | Z322: 0 | AA322: 1 | AB322: 18 | AC322: 1 | AD322: 0 | AE322: 1 | AF322: 0 | AG322: 2.944439 | AH322: 0.69879518 | AI322: 0 | AJ322: 0 | AK322: 0 | AL322: 0 | AM322: 0 | AN322: 0.14285714 | AO322: 0.94339623 | AP322: 0 | AQ322: 0.16666667 | AR322: 0 | AS322: 0.32199318 | AT322: 0.69879518 | AU322: 0.94339623 | AV322: 0 | AW322: 0 | AX322: 0 | AY322: 0 | AZ322: 0.64398635 | BA322: 0 | BB322: 0.016666667 | BC322: 0 | BD322: 0 | BE322: 0.14285714 | BF322: 1.5873826 | BG322: 0.71546185 | BH322: 0.14285714 | BI322: 0.158474 | BJ322: 0.70720504 | BK322: 0.071428571 | BL322: 0.3123692 | BM322: TRUE | BN322: 141509
A323: 178927 | B323: 56 | C323: Aliel Machado | D323: PV | E323: M | F323: 1989-02-26 | G323: Superior Incompleto | H323: 25 | I323: 1460 | J323: 1 | K323: 0 | L323: 0 | M323: 0 | N323: 1 | O323: 32 | P323: 3.4657359 | Q323: 0 | R323: 1 | S323: 0 | T323: 1 | U323: 1 | V323: 0 | W323: 0 | X323: 0 | Y323: 1 | Z323: 1 | AA323: 2 | AB323: 50 | AC323: 1 | AD323: 0 | AE323: 1 | AF323: 0 | AG323: 3.9318256 | AH323: 0.69879518 | AI323: 0 | AJ323: 0 | AK323: 0 | AL323: 0.2 | AM323: 0.11111111 | AN323: 0.28571429 | AO323: 0.94339623 | AP323: 0 | AQ323: 0.16666667 | AR323: 0 | AS323: 0.4299702 | AT323: 0.69879518 | AU323: 0.94339623 | AV323: 0 | AW323: 0 | AX323: 0 | AY323: 0.6 | AZ323: 0.8599404 | BA323: 0 | BB323: 0.016666667 | BC323: 0 | BD323: 0.11111111 | BE323: 0.28571429 | BF323: 2.4033366 | BG323: 0.71546185 | BH323: 0.3968254 | BI323: 0.23993357 | BJ323: 0.70720504 | BK323: 0.1984127 | BL323: 0.38185043 | BM323: FALSE | BN323: 141509
A324: 178927 | B324: 57 | C324: Aliel Machado | D324: PV | E324: M | F324: 1989-02-26 | G324: Superior Incompleto | H324: 25 | I324: 603 | J324: 1.06 | K324: 0 | L324: 0 | M324: 0 | N324: 2 | O324: 2 | P324: 0.69314718 | Q324: 0 | R324: 1 | S324: 0 | T324: 1 | U324: 0 | V324: 0 | W324: 0 | X324: 0 | Y324: 3 | Z324: 2 | AA324: 2 | AB324: 52 | AC324: 1.02 | AD324: 0 | AE324: 1 | AF324: 0 | AG324: 3.9702919 | AH324: 0.69879518 | AI324: 0 | AJ324: 0 | AK324: 0 | AL324: 0.6 | AM324: 0.22222222 | AN324: 0.28571429 | AO324: 0.96226415 | AP324: 0 | AQ324: 0.16666667 | AR324: 0 | AS324: 0.43417674 | AT324: 0.69879518 | AU324: 0.96226415 | AV324: 0 | AW324: 0 | AX324: 0 | AY324: 1.8 | AZ324: 0.86835347 | BA324: 0 | BB324: 0.016666667 | BC324: 0 | BD324: 0.22222222 | BE324: 0.28571429 | BF324: 3.6306176 | BG324: 0.71546185 | BH324: 0.50793651 | BI324: 0.36245735 | BJ324: 0.70720504 | BK324: 0.25396825 | BL324: 0.44121021 | BM324: FALSE | BN324: 141509
A325: 178969 | B325: 55 | C325: Fábio Mitidieri | D325: PSD | E325: M | F325: 1977-02-24 | G325: Superior | H325: 37 | I325: 1460 | J325: 1 | K325: 0 | L325: 0 | M325: 0 | N325: 1 | O325: 69 | P325: 4.2341065 | Q325: 0 | R325: 1 | S325: 0 | T325: 1 | U325: 1 | V325: 0 | W325: 0 | X325: 0 | Y325: 1 | Z325: 1 | AA325: 1 | AB325: 69 | AC325: 1 | AD325: 0 | AE325: 1 | AF325: 0 | AG325: 4.2484952 | AH325: 0.55421687 | AI325: 0 | AJ325: 0 | AK325: 0 | AL325: 0.2 | AM325: 0.11111111 | AN325: 0.14285714 | AO325: 0.94339623 | AP325: 0 | AQ325: 0.16666667 | AR325: 0 | AS325: 0.46460004 | AT325: 0.55421687 | AU325: 0.94339623 | AV325: 0 | AW325: 0 | AX325: 0 | AY325: 0.6 | AZ325: 0.92920009 | BA325: 0 | BB325: 0.016666667 | BC325: 0 | BD325: 0.11111111 | BE325: 0.14285714 | BF325: 2.4725963 | BG325: 0.57088353 | BH325: 0.25396825 | BI325: 0.246848 | BJ325: 0.56429523 | BK325: 0.12698413 | BL325: 0.31270912 | BM325: TRUE | BN325: 141504
A326: 178969 | B326: 56 | C326: Fábio Mitidieri | D326: PSD | E326: M | F326: 1977-02-24 | G326: Superior | H326: 37 | I326: 1308 | J326: 0.9 | K326: 0 | L326: 0 | M326: 0 | N326: 1 | O326: 23 | P326: 3.1354942 | Q326: 0 | R326: 1 | S326: 0 | T326: 1 | U326: 0 | V326: 0 | W326: 0 | X326: 0 | Y326: 2 | Z326: 2 | AA326: 1 | AB326: 92 | AC326: 0.95 | AD326: 0 | AE326: 1 | AF326: 0 | AG326: 4.5325995 | AH326: 0.55421687 | AI326: 0 | AJ326: 0 | AK326: 0 | AL326: 0.4 | AM326: 0.22222222 | AN326: 0.14285714 | AO326: 0.89622642 | AP326: 0 | AQ326: 0.16666667 | AR326: 0 | AS326: 0.49566865 | AT326: 0.55421687 | AU326: 0.89622642 | AV326: 0 | AW326: 0 | AX326: 0 | AY326: 1.2 | AZ326: 0.99133731 | BA326: 0 | BB326: 0.016666667 | BC326: 0 | BD326: 0.22222222 | BE326: 0.14285714 | BF326: 3.0875637 | BG326: 0.57088353 | BH326: 0.36507937 | BI326: 0.30824237 | BJ326: 0.56429523 | BK326: 0.18253968 | BL326: 0.35169243 | BM326: FALSE | BN326: 141504
A327: 141433 | B327: 53 | C327: FILIPE PEREIRA | D327: PSC | E327: M | F327: 1983-11-16 | G327: Superior | H327: 23 | I327: 1460 | J327: 1 | K327: 0 | L327: 0 | M327: 0 | N327: 0 | O327: 34 | P327: 3.5263605 | Q327: 0 | R327: 0 | S327: 0 | T327: 0 | U327: 1 | V327: 0 | W327: 0 | X327: 0 | Y327: 0 | Z327: 0 | AA327: 1 | AB327: 34 | AC327: 1 | AD327: 0 | AE327: 0 | AF327: 0 | AG327: 3.5553481 | AH327: 0.72289157 | AI327: 0 | AJ327: 0 | AK327: 0 | AL327: 0 | AM327: 0 | AN327: 0.14285714 | AO327: 0.94339623 | AP327: 0 | AQ327: 0 | AR327: 0 | AS327: 0.38879998 | AT327: 0.72289157 | AU327: 0.94339623 | AV327: 0 | AW327: 0 | AX327: 0 | AY327: 0 | AZ327: 0.77759996 | BA327: 0 | BB327: 0 | BC327: 0 | BD327: 0 | BE327: 0.14285714 | BF327: 1.7209962 | BG327: 0.72289157 | BH327: 0.14285714 | BI327: 0.17181311 | BJ327: 0.71454901 | BK327: 0.071428571 | BL327: 0.31926357 | BM327: TRUE | BN327: 141488
A328: 141433 | B328: 54 | C328: FILIPE PEREIRA | D328: PSC | E328: M | F328: 1983-11-16 | G328: Superior | H328: 23 | I328: 1032 | J328: 0.71 | K328: 0 | L328: 0 | M328: 0 | N328: 4 | O328: 1 | P328: 0 | Q328: 0 | R328: 0 | S328: 0 | T328: 1 | U328: 1 | V328: 0 | W328: 0 | X328: 0 | Y328: 4 | Z328: 1 | AA328: 2 | AB328: 35 | AC328: 0.855 | AD328: 0 | AE328: 0 | AF328: 0 | AG328: 3.5835189 | AH328: 0.72289157 | AI328: 0 | AJ328: 0 | AK328: 0 | AL328: 0.8 | AM328: 0.11111111 | AN328: 0.28571429 | AO328: 0.80660377 | AP328: 0 | AQ328: 0 | AR328: 0 | AS328: 0.39188064 | AT328: 0.72289157 | AU328: 0.80660377 | AV328: 0 | AW328: 0 | AX328: 0 | AY328: 2.4 | AZ328: 0.78376129 | BA328: 0 | BB328: 0 | BC328: 0 | BD328: 0.11111111 | BE328: 0.28571429 | BF328: 3.9903651 | BG328: 0.72289157 | BH328: 0.3968254 | BI328: 0.39837221 | BJ328: 0.71454901 | BK328: 0.1984127 | BL328: 0.43711131 | BM328: TRUE | BN328: 141488
A329: 99654 | B329: 54 | C329: ERIVELTON SANTANA | D329: PATRI | E329: M | F329: 1965-01-29 | G329: Superior Incompleto | H329: 46 | I329: 1460 | J329: 1 | K329: 0 | L329: 0 | M329: 0 | N329: 0 | O329: 16 | P329: 2.7725887 | Q329: 0 | R329: 2 | S329: 0 | T329: 1 | U329: 1 | V329: 0 | W329: 0 | X329: 0 | Y329: 0 | Z329: 1 | AA329: 1 | AB329: 16 | AC329: 1 | AD329: 0 | AE329: 2 | AF329: 0 | AG329: 2.8332133 | AH329: 0.44578313 | AI329: 0 | AJ329: 0 | AK329: 0 | AL329: 0 | AM329: 0.11111111 | AN329: 0.14285714 | AO329: 0.94339623 | AP329: 0 | AQ329: 0.33333333 | AR329: 0 | AS329: 0.30982994 | AT329: 0.44578313 | AU329: 0.94339623 | AV329: 0 | AW329: 0 | AX329: 0 | AY329: 0 | AZ329: 0.61965989 | BA329: 0 | BB329: 0.033333333 | BC329: 0 | BD329: 0.11111111 | BE329: 0.14285714 | BF329: 1.5630561 | BG329: 0.47911647 | BH329: 0.25396825 | BI329: 0.1560454 | BJ329: 0.47358721 | BK329: 0.12698413 | BL329: 0.25220558 | BM329: TRUE | BN329: 141487
A330: 99654 | B330: 55 | C330: ERIVELTON SANTANA | D330: PATRI | E330: M | F330: 1965-01-29 | G330: Superior Incompleto | H330: 46 | I330: 1460 | J330: 1 | K330: 0 | L330: 0 | M330: 0 | N330: 0 | O330: 10 | P330: 2.3025851 | Q330: 0 | R330: 2 | S330: 0 | T330: 1 | U330: 1 | V330: 0 | W330: 0 | X330: 0 | Y330: 0 | Z330: 2 | AA330: 2 | AB330: 26 | AC330: 1 | AD330: 0 | AE330: 2 | AF330: 0 | AG330: 3.2958369 | AH330: 0.44578313 | AI330: 0 | AJ330: 0 | AK330: 0 | AL330: 0 | AM330: 0.22222222 | AN330: 0.28571429 | AO330: 0.94339623 | AP330: 0 | AQ330: 0.33333333 | AR330: 0 | AS330: 0.36042078 | AT330: 0.44578313 | AU330: 0.94339623 | AV330: 0 | AW330: 0 | AX330: 0 | AY330: 0 | AZ330: 0.72084155 | BA330: 0 | BB330: 0.033333333 | BC330: 0 | BD330: 0.22222222 | BE330: 0.28571429 | BF330: 1.6642378 | BG330: 0.47911647 | BH330: 0.50793651 | BI330: 0.16614672 | BJ330: 0.47358721 | BK330: 0.25396825 | BL330: 0.29790073 | BM330: TRUE | BN330: 141487
A331: 220595 | B331: 57 | C331: Coronel Fernanda | D331: PL | E331: F | F331: 1974-11-13 | G331: Superior | H331: 48 | I331: 603 | J331: 1.06 | K331: 0 | L331: 0 | M331: 0 | N331: 0 | O331: 29 | P331: 3.3672958 | Q331: 0 | R331: 0 | S331: 0 | T331: 1 | U331: 0 | V331: 0 | W331: 0 | X331: 0 | Y331: 0 | Z331: 1 | AA331: 0 | AB331: 29 | AC331: 1.06 | AD331: 0 | AE331: 0 | AF331: 0 | AG331: 3.4011974 | AH331: 0.42168675 | AI331: 0 | AJ331: 0 | AK331: 0 | AL331: 0 | AM331: 0.11111111 | AN331: 0 | AO331: 1 | AP331: 0 | AQ331: 0 | AR331: 0 | AS331: 0.37194262 | AT331: 0.42168675 | AU331: 1 | AV331: 0 | AW331: 0 | AX331: 0 | AY331: 0 | AZ331: 0.74388524 | BA331: 0 | BB331: 0 | BC331: 0 | BD331: 0.11111111 | BE331: 0 | BF331: 1.7438852 | BG331: 0.42168675 | BH331: 0.11111111 | BI331: 0.17409821 | BJ331: 0.41682026 | BK331: 0.055555556 | BL331: 0.21549134 | BM331: TRUE | BN331: 141486
...
